<?xml version="1.0"?>
<robot name="abb_irb52_7_120"
       xmlns:xi="http://www.w3.org/2001/XInclude">
  <link name="base_link">
    <visual>
      <origin xyz="-0.052131 0.000131004 0.0855" rpy="0 -0 0"/>
      <geometry>
         <box size="0.660262 0.483268 0.171"/>
      </geometry>
    </visual>
    <collision>
      <origin xyz="-0.052131 0.000131004 0.0855" rpy="0 -0 0"/>
      <geometry>
         <box size="0.660262 0.483268 0.171"/>
      </geometry>
    </collision>
  </link>
  <link name="base">
  </link>
  <link name="link_1">
    <visual>
      <origin xyz="0.0271685 0.0329565 -0.0935005" rpy="0 -0 0"/>
      <geometry>
         <box size="0.582649 0.391913 0.536999"/>
      </geometry>
    </visual>
    <collision>
      <origin xyz="0.0271685 0.0329565 -0.0935005" rpy="0 -0 0"/>
      <geometry>
         <box size="0.582649 0.391913 0.536999"/>
      </geometry>
    </collision>
  </link>
  <link name="link_2">
    <visual>
      <origin xyz="-0.0088293 -0.1795 0.228161" rpy="0 -0 0"/>
      <geometry>
         <box size="0.223339 0.146 0.632866"/>
      </geometry>
    </visual>
    <collision>
      <origin xyz="-0.0088293 -0.1795 0.228161" rpy="0 -0 0"/>
      <geometry>
         <box size="0.223339 0.146 0.632866"/>
      </geometry>
    </collision>
  </link>
  <link name="link_3">
    <visual>
      <origin xyz="0.0681975 0.0243125 -0.0139365" rpy="0 -0 0"/>
      <geometry>
         <box size="0.491605 0.288625 0.243813"/>
      </geometry>
    </visual>
    <collision>
      <origin xyz="0.0681975 0.0243125 -0.0139365" rpy="0 -0 0"/>
      <geometry>
         <box size="0.491605 0.288625 0.243813"/>
      </geometry>
    </collision>
  </link>
  <link name="link_4">
    <visual>
      <origin xyz="0.485 0.0027625 -5.02914e-08" rpy="0 -0 0"/>
      <geometry>
         <box size="0.342 0.134475 0.112"/>
      </geometry>
    </visual>
    <collision>
      <origin xyz="0.485 0.0027625 -5.02914e-08" rpy="0 -0 0"/>
      <geometry>
         <box size="0.342 0.134475 0.112"/>
      </geometry>
    </collision>
  </link>
  <link name="link_5">
    <visual>
      <origin xyz="-2.38419e-08 0 2.78503e-05" rpy="0 -0 0"/>
      <geometry>
         <box size="0.084 0.0273 0.0839443"/>
      </geometry>
    </visual>
    <collision>
      <origin xyz="-2.38419e-08 0 2.78503e-05" rpy="0 -0 0"/>
      <geometry>
         <box size="0.084 0.0273 0.0839443"/>
      </geometry>
    </collision>
  </link>
  <link name="link_6">
    <visual>
      <origin xyz="-0.0325 0 -5.02914e-08" rpy="0 -0 0"/>
      <geometry>
         <box size="0.065 0.0499682 0.0499901"/>
      </geometry>
    </visual>
    <collision>
      <origin xyz="-0.0325 0 -5.02914e-08" rpy="0 -0 0"/>
      <geometry>
         <box size="0.065 0.0499682 0.0499901"/>
      </geometry>
    </collision>
  </link>
  <link name="tool0">
  </link>
  <joint name="base_link-base" type="fixed">
    <parent link="base_link"/>
    <child  link="base"/>
    <origin xyz="0 0 0" rpy="0 -0 0 "/>
    <axis   xyz="0 0 0"/>
    <limit lower="0" upper="0" effort="100" velocity="0.5" />
    <dynamics damping="0.2" friction="0" />
  </joint>
  <joint name="joint_1" type="revolute">
    <parent link="base_link"/>
    <child  link="link_1"/>
    <origin xyz="0 0 0.4865" rpy="0 -0 0 "/>
    <axis   xyz="0 0 1"/>
    <limit lower="-3.14159" upper="3.14159" effort="100" velocity="3.14159" />
    <dynamics damping="0.2" friction="0" />
  </joint>
  <joint name="joint_2" type="revolute">
    <parent link="link_1"/>
    <child  link="link_2"/>
    <origin xyz="0.15 0 0" rpy="0 -0 0 "/>
    <axis   xyz="0 1 0"/>
    <limit lower="-1.09956" upper="1.91986" effort="100" velocity="3.14159" />
    <dynamics damping="0.2" friction="0" />
  </joint>
  <joint name="joint_3" type="revolute">
    <parent link="link_2"/>
    <child  link="link_3"/>
    <origin xyz="0 0 0.475" rpy="0 -0 0 "/>
    <axis   xyz="0 1 0"/>
    <limit lower="-4.10152" upper="0.959931" effort="100" velocity="3.14159" />
    <dynamics damping="0.2" friction="0" />
  </joint>
  <joint name="joint_4" type="revolute">
    <parent link="link_3"/>
    <child  link="link_4"/>
    <origin xyz="0 0 0" rpy="0 -0 0 "/>
    <axis   xyz="1 0 0"/>
    <limit lower="-3.49066" upper="3.49066" effort="100" velocity="3.14159" />
    <dynamics damping="0.2" friction="0" />
  </joint>
  <joint name="joint_5" type="revolute">
    <parent link="link_4"/>
    <child  link="link_5"/>
    <origin xyz="0.6 0 0" rpy="0 -0 0 "/>
    <axis   xyz="0 1 0"/>
    <limit lower="-2.00713" upper="2.00713" effort="100" velocity="3.14159" />
    <dynamics damping="0.2" friction="0" />
  </joint>
  <joint name="joint_6" type="revolute">
    <parent link="link_5"/>
    <child  link="link_6"/>
    <origin xyz="0.065 0 0" rpy="0 -0 0 "/>
    <axis   xyz="1 0 0"/>
    <limit lower="-6.98132" upper="6.98132" effort="100" velocity="3.14159" />
    <dynamics damping="0.2" friction="0" />
  </joint>
  <joint name="joint_6-tool0" type="fixed">
    <parent link="link_6"/>
    <child  link="tool0"/>
    <origin xyz="0 0 0" rpy="0 1.5708 -0 "/>
    <axis   xyz="0 0 0"/>
    <limit lower="0" upper="0" effort="100" velocity="0.5" />
    <dynamics damping="0.2" friction="0" />
  </joint>
</robot>
